Workbook

Sheet Summary
A1: 2027 Covenant Test Summary
A2: Every test was read from the loan documents.
A3: =HYPERLINK("#'2027 Calendar'!A1","Dated calendar") -> Dated calendar | B3: =HYPERLINK("#'Ongoing Obligations'!A1","Ongoing obligations") -> Ongoing obligations | C3: =HYPERLINK("#'Property Reference'!A1","Property reference") -> Property reference
A5: 2027 monthly workload
A6: Month | B6: New tests | C6: Maturities
A7: =DATE(2027,1,1) -> 46388 | B7: =COUNTIFS('2027 Calendar'!$A$5:$A$45,">="&$A7,'2027 Calendar'!$A$5:$A$45,"<"&EDATE($A7,1),'2027 Calendar'!$D$5:$D$45,"Test") -> 0 | C7: =COUNTIFS('2027 Calendar'!$A$5:$A$45,">="&$A7,'2027 Calendar'!$A$5:$A$45,"<"&EDATE($A7,1),'2027 Calendar'!$D$5:$D$45,"Maturity") -> 0
A8: =DATE(2027,2,1) -> 46419 | B8: =COUNTIFS('2027 Calendar'!$A$5:$A$45,">="&$A8,'2027 Calendar'!$A$5:$A$45,"<"&EDATE($A8,1),'2027 Calendar'!$D$5:$D$45,"Test") -> 0 | C8: =COUNTIFS('2027 Calendar'!$A$5:$A$45,">="&$A8,'2027 Calendar'!$A$5:$A$45,"<"&EDATE($A8,1),'2027 Calendar'!$D$5:$D$45,"Maturity") -> 0
A9: =DATE(2027,3,1) -> 46447 | B9: =COUNTIFS('2027 Calendar'!$A$5:$A$45,">="&$A9,'2027 Calendar'!$A$5:$A$45,"<"&EDATE($A9,1),'2027 Calendar'!$D$5:$D$45,"Test") -> 1 | C9: =COUNTIFS('2027 Calendar'!$A$5:$A$45,">="&$A9,'2027 Calendar'!$A$5:$A$45,"<"&EDATE($A9,1),'2027 Calendar'!$D$5:$D$45,"Maturity") -> 0
A10: =DATE(2027,4,1) -> 46478 | B10: =COUNTIFS('2027 Calendar'!$A$5:$A$45,">="&$A10,'2027 Calendar'!$A$5:$A$45,"<"&EDATE($A10,1),'2027 Calendar'!$D$5:$D$45,"Test") -> 2 | C10: =COUNTIFS('2027 Calendar'!$A$5:$A$45,">="&$A10,'2027 Calendar'!$A$5:$A$45,"<"&EDATE($A10,1),'2027 Calendar'!$D$5:$D$45,"Maturity") -> 0
A11: =DATE(2027,5,1) -> 46508 | B11: =COUNTIFS('2027 Calendar'!$A$5:$A$45,">="&$A11,'2027 Calendar'!$A$5:$A$45,"<"&EDATE($A11,1),'2027 Calendar'!$D$5:$D$45,"Test") -> 1 | C11: =COUNTIFS('2027 Calendar'!$A$5:$A$45,">="&$A11,'2027 Calendar'!$A$5:$A$45,"<"&EDATE($A11,1),'2027 Calendar'!$D$5:$D$45,"Maturity") -> 1
A12: =DATE(2027,6,1) -> 46539 | B12: =COUNTIFS('2027 Calendar'!$A$5:$A$45,">="&$A12,'2027 Calendar'!$A$5:$A$45,"<"&EDATE($A12,1),'2027 Calendar'!$D$5:$D$45,"Test") -> 1 | C12: =COUNTIFS('2027 Calendar'!$A$5:$A$45,">="&$A12,'2027 Calendar'!$A$5:$A$45,"<"&EDATE($A12,1),'2027 Calendar'!$D$5:$D$45,"Maturity") -> 0
A13: =DATE(2027,7,1) -> 46569 | B13: =COUNTIFS('2027 Calendar'!$A$5:$A$45,">="&$A13,'2027 Calendar'!$A$5:$A$45,"<"&EDATE($A13,1),'2027 Calendar'!$D$5:$D$45,"Test") -> 0 | C13: =COUNTIFS('2027 Calendar'!$A$5:$A$45,">="&$A13,'2027 Calendar'!$A$5:$A$45,"<"&EDATE($A13,1),'2027 Calendar'!$D$5:$D$45,"Maturity") -> 0
A14: =DATE(2027,8,1) -> 46600 | B14: =COUNTIFS('2027 Calendar'!$A$5:$A$45,">="&$A14,'2027 Calendar'!$A$5:$A$45,"<"&EDATE($A14,1),'2027 Calendar'!$D$5:$D$45,"Test") -> 1 | C14: =COUNTIFS('2027 Calendar'!$A$5:$A$45,">="&$A14,'2027 Calendar'!$A$5:$A$45,"<"&EDATE($A14,1),'2027 Calendar'!$D$5:$D$45,"Maturity") -> 0
A15: =DATE(2027,9,1) -> 46631 | B15: =COUNTIFS('2027 Calendar'!$A$5:$A$45,">="&$A15,'2027 Calendar'!$A$5:$A$45,"<"&EDATE($A15,1),'2027 Calendar'!$D$5:$D$45,"Test") -> 2 | C15: =COUNTIFS('2027 Calendar'!$A$5:$A$45,">="&$A15,'2027 Calendar'!$A$5:$A$45,"<"&EDATE($A15,1),'2027 Calendar'!$D$5:$D$45,"Maturity") -> 0
A16: =DATE(2027,10,1) -> 46661 | B16: =COUNTIFS('2027 Calendar'!$A$5:$A$45,">="&$A16,'2027 Calendar'!$A$5:$A$45,"<"&EDATE($A16,1),'2027 Calendar'!$D$5:$D$45,"Test") -> 0 | C16: =COUNTIFS('2027 Calendar'!$A$5:$A$45,">="&$A16,'2027 Calendar'!$A$5:$A$45,"<"&EDATE($A16,1),'2027 Calendar'!$D$5:$D$45,"Maturity") -> 0
A17: =DATE(2027,11,1) -> 46692 | B17: =COUNTIFS('2027 Calendar'!$A$5:$A$45,">="&$A17,'2027 Calendar'!$A$5:$A$45,"<"&EDATE($A17,1),'2027 Calendar'!$D$5:$D$45,"Test") -> 3 | C17: =COUNTIFS('2027 Calendar'!$A$5:$A$45,">="&$A17,'2027 Calendar'!$A$5:$A$45,"<"&EDATE($A17,1),'2027 Calendar'!$D$5:$D$45,"Maturity") -> 2
A18: =DATE(2027,12,1) -> 46722 | B18: =COUNTIFS('2027 Calendar'!$A$5:$A$45,">="&$A18,'2027 Calendar'!$A$5:$A$45,"<"&EDATE($A18,1),'2027 Calendar'!$D$5:$D$45,"Test") -> 4 | C18: =COUNTIFS('2027 Calendar'!$A$5:$A$45,">="&$A18,'2027 Calendar'!$A$5:$A$45,"<"&EDATE($A18,1),'2027 Calendar'!$D$5:$D$45,"Maturity") -> 2
A19: Total | B19: =SUM(B7:B18) -> 15 | C19: =SUM(C7:C18) -> 5
A21: New tests are counted once, on their first date, and exclude ongoing obligations.
A23: Property | B23: Lender | C23: Maturity | D23: First New Test | E23: New Tests
A24: =HYPERLINK("#'Property Reference'!B5",'Property Reference'!B5) -> Dove Valley | B24: ='Property Reference'!C5 -> Nationwide | C24: ='Property Reference'!D5 -> 46692 | D24: ='Property Reference'!F5 -> 46692 | E24: ='Property Reference'!G5 -> 1
A25: =HYPERLINK("#'Property Reference'!B6",'Property Reference'!B6) -> Spectrum Loop | B25: ='Property Reference'!C6 -> Nationwide | C25: ='Property Reference'!D6 -> 47014 | D25: ='Property Reference'!F6 -> None | E25: ='Property Reference'!G6 -> 0
A26: =HYPERLINK("#'Property Reference'!B7",'Property Reference'!B7) -> Fort Collins Shields | B26: ='Property Reference'!C7 -> Starwood | C26: ='Property Reference'!D7 -> 46974 | D26: ='Property Reference'!F7 -> 46608 | E26: ='Property Reference'!G7 -> 1
A27: =HYPERLINK("#'Property Reference'!B8",'Property Reference'!B8) -> Fort Collins Vine | B27: ='Property Reference'!C8 -> Western-Southern | C27: ='Property Reference'!D8 -> 47309 | D27: ='Property Reference'!F8 -> None | E27: ='Property Reference'!G8 -> 0
A28: =HYPERLINK("#'Property Reference'!B9",'Property Reference'!B9) -> Ellenton | B28: ='Property Reference'!C9 -> Kayne Anderson | C28: ='Property Reference'!D9 -> 47266 | D28: ='Property Reference'!F9 -> 46660 | E28: ='Property Reference'!G9 -> 2
A29: =HYPERLINK("#'Property Reference'!B10",'Property Reference'!B10) -> Panama City Beach | B29: ='Property Reference'!C10 -> Merchants Bank of Indiana | C29: ='Property Reference'!D10 -> 47766 | D29: ='Property Reference'!F10 -> None | E29: ='Property Reference'!G10 -> 0
A30: =HYPERLINK("#'Property Reference'!B11",'Property Reference'!B11) -> Ponte Vedra | B30: ='Property Reference'!C11 -> Trustmark | C30: ='Property Reference'!D11 -> 47162 | D30: ='Property Reference'!F11 -> None | E30: ='Property Reference'!G11 -> 0
A31: =HYPERLINK("#'Property Reference'!B12",'Property Reference'!B12) -> Port St Lucie | B31: ='Property Reference'!C12 -> Blackstone / FGL | C31: ='Property Reference'!D12 -> 46997 | D31: ='Property Reference'!F12 -> 46477 | E31: ='Property Reference'!G12 -> 1
A32: =HYPERLINK("#'Property Reference'!B13",'Property Reference'!B13) -> Sarasota | B32: ='Property Reference'!C13 -> Stifel | C32: ='Property Reference'!D13 -> 46385 | D32: ='Property Reference'!F13 -> None | E32: ='Property Reference'!G13 -> 0
A33: =HYPERLINK("#'Property Reference'!B14",'Property Reference'!B14) -> St. Augustine | B33: ='Property Reference'!C14 -> Simmons | C33: ='Property Reference'!D14 -> 46748 | D33: ='Property Reference'!F14 -> 46748 | E33: ='Property Reference'!G14 -> 1
A34: =HYPERLINK("#'Property Reference'!B15",'Property Reference'!B15) -> Venice | B34: ='Property Reference'!C15 -> UMB | C34: ='Property Reference'!D15 -> 46519 | D34: ='Property Reference'!F15 -> 46507 | E34: ='Property Reference'!G15 -> 1
A35: =HYPERLINK("#'Property Reference'!B16",'Property Reference'!B16) -> Pooler | B35: ='Property Reference'!C16 -> Fifth Third | C35: ='Property Reference'!D16 -> 46714 | D35: ='Property Reference'!F16 -> 46530 | E35: ='Property Reference'!G16 -> 2
A36: =HYPERLINK("#'Property Reference'!B17",'Property Reference'!B17) -> Stockbridge | B36: ='Property Reference'!C17 -> UMB | C36: ='Property Reference'!D17 -> 46748 | D36: ='Property Reference'!F17 -> 46565 | E36: ='Property Reference'!G17 -> 4
A37: =HYPERLINK("#'Property Reference'!B18",'Property Reference'!B18) -> Nampa Sundance | B37: ='Property Reference'!C18 -> Wintrust | C37: ='Property Reference'!D18 -> 46846 | D37: ='Property Reference'!F18 -> 46507 | E37: ='Property Reference'!G18 -> 1
A38: =HYPERLINK("#'Property Reference'!B19",'Property Reference'!B19) -> 2022 Fund (Barings) | B38: ='Property Reference'!C19 -> Barings (2022 Fund) | C38: ='Property Reference'!D19 -> 46914 | D38: ='Property Reference'!F19 -> None | E38: ='Property Reference'!G19 -> 0
A39: =HYPERLINK("#'Property Reference'!B20",'Property Reference'!B20) -> 2023 Fund (Barings) | B39: ='Property Reference'!C20 -> Barings (2023 Fund) | C39: ='Property Reference'!D20 -> 47401 | D39: ='Property Reference'!F20 -> None | E39: ='Property Reference'!G20 -> 0
A40: =HYPERLINK("#'Property Reference'!B21",'Property Reference'!B21) -> Fayetteville Van Asche | B40: ='Property Reference'!C21 -> Associated / Trustmark | C40: ='Property Reference'!D21 -> 47280 | D40: ='Property Reference'!F21 -> None | E40: ='Property Reference'!G21 -> 0
A41: =HYPERLINK("#'Property Reference'!B22",'Property Reference'!B22) -> Gilbert Val Vista | B41: ='Property Reference'!C22 -> Nationwide | C41: ='Property Reference'!D22 -> 47233 | D41: ='Property Reference'!F22 -> None | E41: ='Property Reference'!G22 -> 0
A42: =HYPERLINK("#'Property Reference'!B23",'Property Reference'!B23) -> Venetucci | B42: ='Property Reference'!C23 -> PNC | C42: ='Property Reference'!D23 -> 47245 | D42: ='Property Reference'!F23 -> None | E42: ='Property Reference'!G23 -> 0
A43: =HYPERLINK("#'Property Reference'!B24",'Property Reference'!B24) -> Longmont Hover | B43: ='Property Reference'!C24 -> Stifel | C43: ='Property Reference'!D24 -> 46923 | D43: ='Property Reference'!F24 -> 46752 | E43: ='Property Reference'!G24 -> 1
...

Sheet 2027 Calendar
A1: 2027 Test Calendar
A2: First test dates and maturities in 2027. Tests that started earlier and later recurring dates are in Covenant Tests.
A3: =HYPERLINK("#'Summary'!A1","Back to Summary") -> Back to Summary | E3: =HYPERLINK("#'Ongoing Obligations'!A1","Open ongoing obligations") -> Open ongoing obligations
A4: Date | B4: Property | C4: Lender | D4: Type | E4: Test | F4: Threshold | G4: Occurrence | H4: Reference | I4: Covenant ID
A5: 46477 | B5: =IFERROR(IF(INDEX('Covenant Tests'!$A$2:$A$107,MATCH($I5,'Covenant Tests'!$J$2:$J$107,0))="","",INDEX('Covenant Tests'!$A$2:$A$107,MATCH($I5,'Covenant Tests'!$J$2:$J$107,0))),"Source record missing") -> Port St Lucie | C5: =IFERROR(IF(INDEX('Covenant Tests'!$B$2:$B$107,MATCH($I5,'Covenant Tests'!$J$2:$J$107,0))="","",INDEX('Covenant Tests'!$B$2:$B$107,MATCH($I5,'Covenant Tests'!$J$2:$J$107,0))),"Source record missing") -> Blackstone / FGL | D5: Test | E5: Cash trap: Debt Yield and DSCR | F5: 8.00% and 1.25x | G5: First test, then quarterly | H5: =IFERROR(IF(INDEX('Covenant Tests'!$I$2:$I$107,MATCH($I5,'Covenant Tests'!$J$2:$J$107,0))="","",INDEX('Covenant Tests'!$I$2:$I$107,MATCH($I5,'Covenant Tests'!$J$2:$J$107,0))),"Source record missing") -> Loan Agreement 1.1, Cash Trap Event | I5: CT023
A6: =INDEX('Covenant Tests'!$F$2:$F$107,MATCH($I6,'Covenant Tests'!$J$2:$J$107,0)) -> 46507 | B6: =IFERROR(IF(INDEX('Covenant Tests'!$A$2:$A$107,MATCH($I6,'Covenant Tests'!$J$2:$J$107,0))="","",INDEX('Covenant Tests'!$A$2:$A$107,MATCH($I6,'Covenant Tests'!$J$2:$J$107,0))),"Source record missing") -> Venice | C6: =IFERROR(IF(INDEX('Covenant Tests'!$B$2:$B$107,MATCH($I6,'Covenant Tests'!$J$2:$J$107,0))="","",INDEX('Covenant Tests'!$B$2:$B$107,MATCH($I6,'Covenant Tests'!$J$2:$J$107,0))),"Source record missing") -> UMB | D6: Test | E6: Extension: DSCR | F6: =IFERROR(IF(INDEX('Covenant Tests'!$D$2:$D$107,MATCH($I6,'Covenant Tests'!$J$2:$J$107,0))="","",INDEX('Covenant Tests'!$D$2:$D$107,MATCH($I6,'Covenant Tests'!$J$2:$J$107,0))),"Source record missing") -> 1.10x | G6: Once | H6: =IFERROR(IF(INDEX('Covenant Tests'!$I$2:$I$107,MATCH($I6,'Covenant Tests'!$J$2:$J$107,0))="","",INDEX('Covenant Tests'!$I$2:$I$107,MATCH($I6,'Covenant Tests'!$J$2:$J$107,0))),"Source record missing") -> Note, Section 1 | I6: CT038
A7: =INDEX('Covenant Tests'!$F$2:$F$107,MATCH($I7,'Covenant Tests'!$J$2:$J$107,0)) -> 46507 | B7: =IFERROR(IF(INDEX('Covenant Tests'!$A$2:$A$107,MATCH($I7,'Covenant Tests'!$J$2:$J$107,0))="","",INDEX('Covenant Tests'!$A$2:$A$107,MATCH($I7,'Covenant Tests'!$J$2:$J$107,0))),"Source record missing") -> Nampa Sundance | C7: =IFERROR(IF(INDEX('Covenant Tests'!$B$2:$B$107,MATCH($I7,'Covenant Tests'!$J$2:$J$107,0))="","",INDEX('Covenant Tests'!$B$2:$B$107,MATCH($I7,'Covenant Tests'!$J$2:$J$107,0))),"Source record missing") -> Wintrust | D7: Test | E7: DSCR covenant, step one | F7: =IFERROR(IF(INDEX('Covenant Tests'!$D$2:$D$107,MATCH($I7,'Covenant Tests'!$J$2:$J$107,0))="","",INDEX('Covenant Tests'!$D$2:$D$107,MATCH($I7,'Covenant Tests'!$J$2:$J$107,0))),"Source record missing") -> 1.00x | G7: Once | H7: =IFERROR(IF(INDEX('Covenant Tests'!$I$2:$I$107,MATCH($I7,'Covenant Tests'!$J$2:$J$107,0))="","",INDEX('Covenant Tests'!$I$2:$I$107,MATCH($I7,'Covenant Tests'!$J$2:$J$107,0))),"Source record missing") -> Loan Agreement 9.3 | I7: CT051
A8: =INDEX('Loan Terms'!$D$2:$D$29,MATCH($B8,'Loan Terms'!$A$2:$A$29,0)) -> 46519 | B8: Venice | C8: =INDEX('Loan Terms'!$B$2:$B$29,MATCH($B8,'Loan Terms'!$A$2:$A$29,0)) -> UMB | D8: Maturity | E8: Initial maturity | H8: Note, Section 1 | I8: Maturity
A9: 46530 | B9: =IFERROR(IF(INDEX('Covenant Tests'!$A$2:$A$107,MATCH($I9,'Covenant Tests'!$J$2:$J$107,0))="","",INDEX('Covenant Tests'!$A$2:$A$107,MATCH($I9,'Covenant Tests'!$J$2:$J$107,0))),"Source record missing") -> Pooler | C9: =IFERROR(IF(INDEX('Covenant Tests'!$B$2:$B$107,MATCH($I9,'Covenant Tests'!$J$2:$J$107,0))="","",INDEX('Covenant Tests'!$B$2:$B$107,MATCH($I9,'Covenant Tests'!$J$2:$J$107,0))),"Source record missing") -> Fifth Third | D9: Test | E9: DSCR covenant, step one | F9: =IFERROR(IF(INDEX('Covenant Tests'!$D$2:$D$107,MATCH($I9,'Covenant Tests'!$J$2:$J$107,0))="","",INDEX('Covenant Tests'!$D$2:$D$107,MATCH($I9,'Covenant Tests'!$J$2:$J$107,0))),"Source record missing") -> 1.00x, at rents no lower than the Proforma Rents | G9: Standing covenant from 5/23/2027 until step two | H9: =IFERROR(IF(INDEX('Covenant Tests'!$I$2:$I$107,MATCH($I9,'Covenant Tests'!$J$2:$J$107,0))="","",INDEX('Covenant Tests'!$I$2:$I$107,MATCH($I9,'Covenant Tests'!$J$2:$J$107,0))),"Source record missing") -> Loan Agreement 9.8 | I9: CT042
A10: 46565 | B10: =IFERROR(IF(INDEX('Covenant Tests'!$A$2:$A$107,MATCH($I10,'Covenant Tests'!$J$2:$J$107,0))="","",INDEX('Covenant Tests'!$A$2:$A$107,MATCH($I10,'Covenant Tests'!$J$2:$J$107,0))),"Source record missing") -> Stockbridge | C10: =IFERROR(IF(INDEX('Covenant Tests'!$B$2:$B$107,MATCH($I10,'Covenant Tests'!$J$2:$J$107,0))="","",INDEX('Covenant Tests'!$B$2:$B$107,MATCH($I10,'Covenant Tests'!$J$2:$J$107,0))),"Source record missing") -> UMB | D10: Test | E10: Occupancy, step one | F10: 50% occupancy | G10: Standing covenant from 6/27/2027 | H10: =IFERROR(IF(INDEX('Covenant Tests'!$I$2:$I$107,MATCH($I10,'Covenant Tests'!$J$2:$J$107,0))="","",INDEX('Covenant Tests'!$I$2:$I$107,MATCH($I10,'Covenant Tests'!$J$2:$J$107,0))),"Source record missing") -> Loan Agreement 7.25 | I10: CT047
A11: 46608 | B11: =IFERROR(IF(INDEX('Covenant Tests'!$A$2:$A$107,MATCH($I11,'Covenant Tests'!$J$2:$J$107,0))="","",INDEX('Covenant Tests'!$A$2:$A$107,MATCH($I11,'Covenant Tests'!$J$2:$J$107,0))),"Source record missing") -> Fort Collins Shields | C11: =IFERROR(IF(INDEX('Covenant Tests'!$B$2:$B$107,MATCH($I11,'Covenant Tests'!$J$2:$J$107,0))="","",INDEX('Covenant Tests'!$B$2:$B$107,MATCH($I11,'Covenant Tests'!$J$2:$J$107,0))),"Source record missing") -> Starwood | D11: Test | E11: Cash trap: Debt Yield | F11: =IFERROR(IF(INDEX('Covenant Tests'!$D$2:$D$107,MATCH($I11,'Covenant Tests'!$J$2:$J$107,0))="","",INDEX('Covenant Tests'!$D$2:$D$107,MATCH($I11,'Covenant Tests'!$J$2:$J$107,0))),"Source record missing") -> 6.50% (6.75% for two straight quarters to release) | G11: Any time from the August 2027 payment date; tested off the quarterly Debt Yield calculations | H11: =IFERROR(IF(INDEX('Covenant Tests'!$I$2:$I$107,MATCH($I11,'Covenant Tests'!$J$2:$J$107,0))="","",INDEX('Covenant Tests'!$I$2:$I$107,MATCH($I11,'Covenant Tests'!$J$2:$J$107,0))),"Source record missing") -> Loan Agreement 1.1, Cash Management Event | I11: CT009
A12: 46660 | B12: =IFERROR(IF(INDEX('Covenant Tests'!$A$2:$A$107,MATCH($I12,'Covenant Tests'!$J$2:$J$107,0))="","",INDEX('Covenant Tests'!$A$2:$A$107,MATCH($I12,'Covenant Tests'!$J$2:$J$107,0))),"Source record missing") -> Ellenton | C12: =IFERROR(IF(INDEX('Covenant Tests'!$B$2:$B$107,MATCH($I12,'Covenant Tests'!$J$2:$J$107,0))="","",INDEX('Covenant Tests'!$B$2:$B$107,MATCH($I12,'Covenant Tests'!$J$2:$J$107,0))),"Source record missing") -> Kayne Anderson | D12: Test | E12: Debt Yield | F12: =IFERROR(IF(INDEX('Covenant Tests'!$D$2:$D$107,MATCH($I12,'Covenant Tests'!$J$2:$J$107,0))="","",INDEX('Covenant Tests'!$D$2:$D$107,MATCH($I12,'Covenant Tests'!$J$2:$J$107,0))),"Source record missing") -> 6.00% (7.00% to release) | G12: First test, then quarterly | H12: =IFERROR(IF(INDEX('Covenant Tests'!$I$2:$I$107,MATCH($I12,'Covenant Tests'!$J$2:$J$107,0))="","",INDEX('Covenant Tests'!$I$2:$I$107,MATCH($I12,'Covenant Tests'!$J$2:$J$107,0))),"Source record missing") -> Loan Agreement 2.5(a) | I12: CT014
A13: 46660 | B13: =IFERROR(IF(INDEX('Covenant Tests'!$A$2:$A$107,MATCH($I13,'Covenant Tests'!$J$2:$J$107,0))="","",INDEX('Covenant Tests'!$A$2:$A$107,MATCH($I13,'Covenant Tests'!$J$2:$J$107,0))),"Source record missing") -> Ellenton | C13: =IFERROR(IF(INDEX('Covenant Tests'!$B$2:$B$107,MATCH($I13,'Covenant Tests'!$J$2:$J$107,0))="","",INDEX('Covenant Tests'!$B$2:$B$107,MATCH($I13,'Covenant Tests'!$J$2:$J$107,0))),"Source record missing") -> Kayne Anderson | D13: Test | E13: Implied DSCR | F13: =IFERROR(IF(INDEX('Covenant Tests'!$D$2:$D$107,MATCH($I13,'Covenant Tests'!$J$2:$J$107,0))="","",INDEX('Covenant Tests'!$D$2:$D$107,MATCH($I13,'Covenant Tests'!$J$2:$J$107,0))),"Source record missing") -> 1.00x (1.05x to release) | G13: First test, then quarterly | H13: =IFERROR(IF(INDEX('Covenant Tests'!$I$2:$I$107,MATCH($I13,'Covenant Tests'!$J$2:$J$107,0))="","",INDEX('Covenant Tests'!$I$2:$I$107,MATCH($I13,'Covenant Tests'!$J$2:$J$107,0))),"Source record missing") -> Loan Agreement 2.5(b) | I13: CT015
A14: =INDEX('Covenant Tests'!$F$2:$F$107,MATCH($I14,'Covenant Tests'!$J$2:$J$107,0)) -> 46692 | B14: =IFERROR(IF(INDEX('Covenant Tests'!$A$2:$A$107,MATCH($I14,'Covenant Tests'!$J$2:$J$107,0))="","",INDEX('Covenant Tests'!$A$2:$A$107,MATCH($I14,'Covenant Tests'!$J$2:$J$107,0))),"Source record missing") -> Dove Valley | C14: =IFERROR(IF(INDEX('Covenant Tests'!$B$2:$B$107,MATCH($I14,'Covenant Tests'!$J$2:$J$107,0))="","",INDEX('Covenant Tests'!$B$2:$B$107,MATCH($I14,'Covenant Tests'!$J$2:$J$107,0))),"Source record missing") -> Nationwide | D14: Test | E14: Extension: Net Cash Flow coverage | F14: =IFERROR(IF(INDEX('Covenant Tests'!$D$2:$D$107,MATCH($I14,'Covenant Tests'!$J$2:$J$107,0))="","",INDEX('Covenant Tests'!$D$2:$D$107,MATCH($I14,'Covenant Tests'!$J$2:$J$107,0))),"Source record missing") -> 105% of interest at the 8.50% Base Rate | G14: Once | H14: =IFERROR(IF(INDEX('Covenant Tests'!$I$2:$I$107,MATCH($I14,'Covenant Tests'!$J$2:$J$107,0))="","",INDEX('Covenant Tests'!$I$2:$I$107,MATCH($I14,'Covenant Tests'!$J$2:$J$107,0))),"Source record missing") -> Loan Agreement 3.7(g) | I14: CT001
A15: =INDEX('Loan Terms'!$D$2:$D$29,MATCH($B15,'Loan Terms'!$A$2:$A$29,0)) -> 46692 | B15: Dove Valley | C15: =INDEX('Loan Terms'!$B$2:$B$29,MATCH($B15,'Loan Terms'!$A$2:$A$29,0)) -> Nationwide | D15: Maturity | E15: Initial maturity | H15: Loan Agreement, Initial Maturity Date | I15: Maturity
A16: 46714 | B16: =IFERROR(IF(INDEX('Covenant Tests'!$A$2:$A$107,MATCH($I16,'Covenant Tests'!$J$2:$J$107,0))="","",INDEX('Covenant Tests'!$A$2:$A$107,MATCH($I16,'Covenant Tests'!$J$2:$J$107,0))),"Source record missing") -> Pooler | C16: =IFERROR(IF(INDEX('Covenant Tests'!$B$2:$B$107,MATCH($I16,'Covenant Tests'!$J$2:$J$107,0))="","",INDEX('Covenant Tests'!$B$2:$B$107,MATCH($I16,'Covenant Tests'!$J$2:$J$107,0))),"Source record missing") -> Fifth Third | D16: Test | E16: DSCR: extension test and covenant step two | F16: =IFERROR(IF(INDEX('Covenant Tests'!$D$2:$D$107,MATCH($I16,'Covenant Tests'!$J$2:$J$107,0))="","",INDEX('Covenant Tests'!$D$2:$D$107,MATCH($I16,'Covenant Tests'!$J$2:$J$107,0))),"Source record missing") -> 1.20x | G16: Extension tested once; covenant from 11/23/2027 at the latest, then each 6/30 and 12/31 | H16: Note, Section 8; Loan Agreement 9.8 | I16: CT044
A17: =INDEX('Loan Terms'!$D$2:$D$29,MATCH($B17,'Loan Terms'!$A$2:$A$29,0)) -> 46714 | B17: Pooler | C17: =INDEX('Loan Terms'!$B$2:$B$29,MATCH($B17,'Loan Terms'!$A$2:$A$29,0)) -> Fifth Third | D17: Maturity | E17: Initial maturity | H17: Note, Section 8 | I17: Maturity
A18: =INDEX('Covenant Tests'!$F$2:$F$107,MATCH($I18,'Covenant Tests'!$J$2:$J$107,0)) -> 46721 | B18: =IFERROR(IF(INDEX('Covenant Tests'!$A$2:$A$107,MATCH($I18,'Covenant Tests'!$J$2:$J$107,0))="","",INDEX('Covenant Tests'!$A$2:$A$107,MATCH($I18,'Covenant Tests'!$J$2:$J$107,0))),"Source record missing") -> Stockbridge | C18: =IFERROR(IF(INDEX('Covenant Tests'!$B$2:$B$107,MATCH($I18,'Covenant Tests'!$J$2:$J$107,0))="","",INDEX('Covenant Tests'!$B$2:$B$107,MATCH($I18,'Covenant Tests'!$J$2:$J$107,0))),"Source record missing") -> UMB | D18: Test | E18: Extension: DSCR | F18: =IFERROR(IF(INDEX('Covenant Tests'!$D$2:$D$107,MATCH($I18,'Covenant Tests'!$J$2:$J$107,0))="","",INDEX('Covenant Tests'!$D$2:$D$107,MATCH($I18,'Covenant Tests'!$J$2:$J$107,0))),"Source record missing") -> 1.15x | G18: Once | H18: =IFERROR(IF(INDEX('Covenant Tests'!$I$2:$I$107,MATCH($I18,'Covenant Tests'!$J$2:$J$107,0))="","",INDEX('Covenant Tests'!$I$2:$I$107,MATCH($I18,'Covenant Tests'!$J$2:$J$107,0))),"Source record missing") -> Note, Section 2 | I18: CT048
A19: =INDEX('Covenant Tests'!$F$2:$F$107,MATCH($I19,'Covenant Tests'!$J$2:$J$107,0)) -> 46748 | B19: =IFERROR(IF(INDEX('Covenant Tests'!$A$2:$A$107,MATCH($I19,'Covenant Tests'!$J$2:$J$107,0))="","",INDEX('Covenant Tests'!$A$2:$A$107,MATCH($I19,'Covenant Tests'!$J$2:$J$107,0))),"Source record missing") -> St. Augustine | C19: =IFERROR(IF(INDEX('Covenant Tests'!$B$2:$B$107,MATCH($I19,'Covenant Tests'!$J$2:$J$107,0))="","",INDEX('Covenant Tests'!$B$2:$B$107,MATCH($I19,'Covenant Tests'!$J$2:$J$107,0))),"Source record missing") -> Simmons | D19: Test | E19: Extension: DSCR | F19: =IFERROR(IF(INDEX('Covenant Tests'!$D$2:$D$107,MATCH($I19,'Covenant Tests'!$J$2:$J$107,0))="","",INDEX('Covenant Tests'!$D$2:$D$107,MATCH($I19,'Covenant Tests'!$J$2:$J$107,0))),"Source record missing") -> 1.25x | G19: Once | H19: =IFERROR(IF(INDEX('Covenant Tests'!$I$2:$I$107,MATCH($I19,'Covenant Tests'!$J$2:$J$107,0))="","",INDEX('Covenant Tests'!$I$2:$I$107,MATCH($I19,'Covenant Tests'!$J$2:$J$107,0))),"Source record missing") -> Note, Extension | I19: CT034
A20: =INDEX('Loan Terms'!$D$2:$D$29,MATCH($B20,'Loan Terms'!$A$2:$A$29,0)) -> 46748 | B20: St. Augustine | C20: =INDEX('Loan Terms'!$B$2:$B$29,MATCH($B20,'Loan Terms'!$A$2:$A$29,0)) -> Simmons | D20: Maturity | E20: Initial maturity | H20: Loan Agreement, Maturity Date | I20: Maturity
A21: 46748 | B21: =IFERROR(IF(INDEX('Covenant Tests'!$A$2:$A$107,MATCH($I21,'Covenant Tests'!$J$2:$J$107,0))="","",INDEX('Covenant Tests'!$A$2:$A$107,MATCH($I21,'Covenant Tests'!$J$2:$J$107,0))),"Source record missing") -> Stockbridge | C21: =IFERROR(IF(INDEX('Covenant Tests'!$B$2:$B$107,MATCH($I21,'Covenant Tests'!$J$2:$J$107,0))="","",INDEX('Covenant Tests'!$B$2:$B$107,MATCH($I21,'Covenant Tests'!$J$2:$J$107,0))),"Source record missing") -> UMB | D21: Test | E21: Occupancy, step two | F21: 80% occupancy | G21: Standing covenant from 12/27/2027 | H21: =IFERROR(IF(INDEX('Covenant Tests'!$I$2:$I$107,MATCH($I21,'Covenant Tests'!$J$2:$J$107,0))="","",INDEX('Covenant Tests'!$I$2:$I$107,MATCH($I21,'Covenant Tests'!$J$2:$J$107,0))),"Source record missing") -> Loan Agreement 7.25 | I21: CT047
A22: 46748 | B22: =IFERROR(IF(INDEX('Covenant Tests'!$A$2:$A$107,MATCH($I22,'Covenant Tests'!$J$2:$J$107,0))="","",INDEX('Covenant Tests'!$A$2:$A$107,MATCH($I22,'Covenant Tests'!$J$2:$J$107,0))),"Source record missing") -> Stockbridge | C22: =IFERROR(IF(INDEX('Covenant Tests'!$B$2:$B$107,MATCH($I22,'Covenant Tests'!$J$2:$J$107,0))="","",INDEX('Covenant Tests'!$B$2:$B$107,MATCH($I22,'Covenant Tests'!$J$2:$J$107,0))),"Source record missing") -> UMB | D22: Test | E22: DSCR covenant | F22: =IFERROR(IF(INDEX('Covenant Tests'!$D$2:$D$107,MATCH($I22,'Covenant Tests'!$J$2:$J$107,0))="","",INDEX('Covenant Tests'!$D$2:$D$107,MATCH($I22,'Covenant Tests'!$J$2:$J$107,0))),"Source record missing") -> 1.15x | G22: 12/27/2027, then each 6/30 and 12/31 | H22: =IFERROR(IF(INDEX('Covenant Tests'!$I$2:$I$107,MATCH($I22,'Covenant Tests'!$J$2:$J$107,0))="","",INDEX('Covenant Tests'!$I$2:$I$107,MATCH($I22,'Covenant Tests'!$J$2:$J$107,0))),"Source record missing") -> Loan Agreement 7.20 | I22: CT049
A23: =INDEX('Loan Terms'!$D$2:$D$29,MATCH($B23,'Loan Terms'!$A$2:$A$29,0)) -> 46748 | B23: Stockbridge | C23: =INDEX('Loan Terms'!$B$2:$B$29,MATCH($B23,'Loan Terms'!$A$2:$A$29,0)) -> UMB | D23: Maturity | E23: Initial maturity | H23: Note, Section 2 | I23: Maturity
A24: =INDEX('Covenant Tests'!$F$2:$F$107,MATCH($I24,'Covenant Tests'!$J$2:$J$107,0)) -> 46752 | B24: =IFERROR(IF(INDEX('Covenant Tests'!$A$2:$A$107,MATCH($I24,'Covenant Tests'!$J$2:$J$107,0))="","",INDEX('Covenant Tests'!$A$2:$A$107,MATCH($I24,'Covenant Tests'!$J$2:$J$107,0))),"Source record missing") -> Longmont Hover | C24: =IFERROR(IF(INDEX('Covenant Tests'!$B$2:$B$107,MATCH($I24,'Covenant Tests'!$J$2:$J$107,0))="","",INDEX('Covenant Tests'!$B$2:$B$107,MATCH($I24,'Covenant Tests'!$J$2:$J$107,0))),"Source record missing") -> Stifel | D24: Test | E24: DSCR covenant | F24: =IFERROR(IF(INDEX('Covenant Tests'!$D$2:$D$107,MATCH($I24,'Covenant Tests'!$J$2:$J$107,0))="","",INDEX('Covenant Tests'!$D$2:$D$107,MATCH($I24,'Covenant Tests'!$J$2:$J$107,0))),"Source record missing") -> 1.10x | G24: Once | H24: =IFERROR(IF(INDEX('Covenant Tests'!$I$2:$I$107,MATCH($I24,'Covenant Tests'!$J$2:$J$107,0))="","",INDEX('Covenant Tests'!$I$2:$I$107,MATCH($I24,'Covenant Tests'!$J$2:$J$107,0))),"Source record missing") -> Loan Agreement Article 11, Debt Service Coverage Ratio | I24: CT077

Sheet Ongoing Obligations
A1: 2027 Ongoing Obligations
A2: Ongoing and event-driven requirements in effect during 2027. Expand grouped columns for lender and source reference.
A3: =HYPERLINK("#'Summary'!A1","Back to Summary") -> Back to Summary
A4: Property | B4: Lender | C4: Timing Type | D4: Test | E4: Threshold | F4: Timing / Frequency | G4: Reference | H4: Covenant ID
A5: =IFERROR(IF(INDEX('Covenant Tests'!$A$2:$A$107,MATCH($H5,'Covenant Tests'!$J$2:$J$107,0))="","",INDEX('Covenant Tests'!$A$2:$A$107,MATCH($H5,'Covenant Tests'!$J$2:$J$107,0))),"Source record missing") -> Dove Valley | B5: =IFERROR(IF(INDEX('Covenant Tests'!$B$2:$B$107,MATCH($H5,'Covenant Tests'!$J$2:$J$107,0))="","",INDEX('Covenant Tests'!$B$2:$B$107,MATCH($H5,'Covenant Tests'!$J$2:$J$107,0))),"Source record missing") -> Nationwide | C5: =IFERROR(IF(INDEX('Covenant Tests'!$E$2:$E$107,MATCH($H5,'Covenant Tests'!$J$2:$J$107,0))="","",INDEX('Covenant Tests'!$E$2:$E$107,MATCH($H5,'Covenant Tests'!$J$2:$J$107,0))),"Source record missing") -> Ongoing | D5: =HYPERLINK("#'Covenant Tests'!A"&(MATCH($H5,'Covenant Tests'!$J$2:$J$107,0)+1),INDEX('Covenant Tests'!$C$2:$C$107,MATCH($H5,'Covenant Tests'!$J$2:$J$107,0))) -> Cash sweep and distribution block | E5: =IFERROR(IF(INDEX('Covenant Tests'!$D$2:$D$107,MATCH($H5,'Covenant Tests'!$J$2:$J$107,0))="","",INDEX('Covenant Tests'!$D$2:$D$107,MATCH($H5,'Covenant Tests'!$J$2:$J$107,0))),"Source record missing") -> Until final completion, DSCR 1.00x on trailing 3 months and capitalized interest repaid | F5: =IFERROR(IF(INDEX('Covenant Tests'!$G$2:$G$107,MATCH($H5,'Covenant Tests'!$J$2:$J$107,0))="","",INDEX('Covenant Tests'!$G$2:$G$107,MATCH($H5,'Covenant Tests'!$J$2:$J$107,0))),"Source record missing") -> Ongoing; monthly | G5: =IFERROR(IF(INDEX('Covenant Tests'!$I$2:$I$107,MATCH($H5,'Covenant Tests'!$J$2:$J$107,0))="","",INDEX('Covenant Tests'!$I$2:$I$107,MATCH($H5,'Covenant Tests'!$J$2:$J$107,0))),"Source record missing") -> Loan Agreement 3.5, 7.14 | H5: CT003
A6: =IFERROR(IF(INDEX('Covenant Tests'!$A$2:$A$107,MATCH($H6,'Covenant Tests'!$J$2:$J$107,0))="","",INDEX('Covenant Tests'!$A$2:$A$107,MATCH($H6,'Covenant Tests'!$J$2:$J$107,0))),"Source record missing") -> Dove Valley | B6: =IFERROR(IF(INDEX('Covenant Tests'!$B$2:$B$107,MATCH($H6,'Covenant Tests'!$J$2:$J$107,0))="","",INDEX('Covenant Tests'!$B$2:$B$107,MATCH($H6,'Covenant Tests'!$J$2:$J$107,0))),"Source record missing") -> Nationwide | C6: =IFERROR(IF(INDEX('Covenant Tests'!$E$2:$E$107,MATCH($H6,'Covenant Tests'!$J$2:$J$107,0))="","",INDEX('Covenant Tests'!$E$2:$E$107,MATCH($H6,'Covenant Tests'!$J$2:$J$107,0))),"Source record missing") -> Event-driven | D6: =HYPERLINK("#'Covenant Tests'!A"&(MATCH($H6,'Covenant Tests'!$J$2:$J$107,0)+1),INDEX('Covenant Tests'!$C$2:$C$107,MATCH($H6,'Covenant Tests'!$J$2:$J$107,0))) -> Interest reserve top-up | E6: =IFERROR(IF(INDEX('Covenant Tests'!$D$2:$D$107,MATCH($H6,'Covenant Tests'!$J$2:$J$107,0))="","",INDEX('Covenant Tests'!$D$2:$D$107,MATCH($H6,'Covenant Tests'!$J$2:$J$107,0))),"Source record missing") -> Reserve short of projected current pay interest, or loan to cost at 70% | F6: =IFERROR(IF(INDEX('Covenant Tests'!$G$2:$G$107,MATCH($H6,'Covenant Tests'!$J$2:$J$107,0))="","",INDEX('Covenant Tests'!$G$2:$G$107,MATCH($H6,'Covenant Tests'!$J$2:$J$107,0))),"Source record missing") -> On lender notice | G6: =IFERROR(IF(INDEX('Covenant Tests'!$I$2:$I$107,MATCH($H6,'Covenant Tests'!$J$2:$J$107,0))="","",INDEX('Covenant Tests'!$I$2:$I$107,MATCH($H6,'Covenant Tests'!$J$2:$J$107,0))),"Source record missing") -> Loan Agreement 3.4(d) | H6: CT004
A7: =IFERROR(IF(INDEX('Covenant Tests'!$A$2:$A$107,MATCH($H7,'Covenant Tests'!$J$2:$J$107,0))="","",INDEX('Covenant Tests'!$A$2:$A$107,MATCH($H7,'Covenant Tests'!$J$2:$J$107,0))),"Source record missing") -> Spectrum Loop | B7: =IFERROR(IF(INDEX('Covenant Tests'!$B$2:$B$107,MATCH($H7,'Covenant Tests'!$J$2:$J$107,0))="","",INDEX('Covenant Tests'!$B$2:$B$107,MATCH($H7,'Covenant Tests'!$J$2:$J$107,0))),"Source record missing") -> Nationwide | C7: =IFERROR(IF(INDEX('Covenant Tests'!$E$2:$E$107,MATCH($H7,'Covenant Tests'!$J$2:$J$107,0))="","",INDEX('Covenant Tests'!$E$2:$E$107,MATCH($H7,'Covenant Tests'!$J$2:$J$107,0))),"Source record missing") -> Ongoing | D7: =HYPERLINK("#'Covenant Tests'!A"&(MATCH($H7,'Covenant Tests'!$J$2:$J$107,0)+1),INDEX('Covenant Tests'!$C$2:$C$107,MATCH($H7,'Covenant Tests'!$J$2:$J$107,0))) -> Cash sweep and distribution block | E7: =IFERROR(IF(INDEX('Covenant Tests'!$D$2:$D$107,MATCH($H7,'Covenant Tests'!$J$2:$J$107,0))="","",INDEX('Covenant Tests'!$D$2:$D$107,MATCH($H7,'Covenant Tests'!$J$2:$J$107,0))),"Source record missing") -> Until final completion, DSCR 1.00x on trailing 3 months and capitalized interest repaid | F7: =IFERROR(IF(INDEX('Covenant Tests'!$G$2:$G$107,MATCH($H7,'Covenant Tests'!$J$2:$J$107,0))="","",INDEX('Covenant Tests'!$G$2:$G$107,MATCH($H7,'Covenant Tests'!$J$2:$J$107,0))),"Source record missing") -> Ongoing; monthly | G7: =IFERROR(IF(INDEX('Covenant Tests'!$I$2:$I$107,MATCH($H7,'Covenant Tests'!$J$2:$J$107,0))="","",INDEX('Covenant Tests'!$I$2:$I$107,MATCH($H7,'Covenant Tests'!$J$2:$J$107,0))),"Source record missing") -> Loan Agreement 3.5, 7.14 | H7: CT005
A8: =IFERROR(IF(INDEX('Covenant Tests'!$A$2:$A$107,MATCH($H8,'Covenant Tests'!$J$2:$J$107,0))="","",INDEX('Covenant Tests'!$A$2:$A$107,MATCH($H8,'Covenant Tests'!$J$2:$J$107,0))),"Source record missing") -> Spectrum Loop | B8: =IFERROR(IF(INDEX('Covenant Tests'!$B$2:$B$107,MATCH($H8,'Covenant Tests'!$J$2:$J$107,0))="","",INDEX('Covenant Tests'!$B$2:$B$107,MATCH($H8,'Covenant Tests'!$J$2:$J$107,0))),"Source record missing") -> Nationwide | C8: =IFERROR(IF(INDEX('Covenant Tests'!$E$2:$E$107,MATCH($H8,'Covenant Tests'!$J$2:$J$107,0))="","",INDEX('Covenant Tests'!$E$2:$E$107,MATCH($H8,'Covenant Tests'!$J$2:$J$107,0))),"Source record missing") -> Event-driven | D8: =HYPERLINK("#'Covenant Tests'!A"&(MATCH($H8,'Covenant Tests'!$J$2:$J$107,0)+1),INDEX('Covenant Tests'!$C$2:$C$107,MATCH($H8,'Covenant Tests'!$J$2:$J$107,0))) -> Interest reserve top-up | E8: =IFERROR(IF(INDEX('Covenant Tests'!$D$2:$D$107,MATCH($H8,'Covenant Tests'!$J$2:$J$107,0))="","",INDEX('Covenant Tests'!$D$2:$D$107,MATCH($H8,'Covenant Tests'!$J$2:$J$107,0))),"Source record missing") -> Reserve short of projected current pay interest, or loan to cost at 70% | F8: =IFERROR(IF(INDEX('Covenant Tests'!$G$2:$G$107,MATCH($H8,'Covenant Tests'!$J$2:$J$107,0))="","",INDEX('Covenant Tests'!$G$2:$G$107,MATCH($H8,'Covenant Tests'!$J$2:$J$107,0))),"Source record missing") -> On lender notice | G8: =IFERROR(IF(INDEX('Covenant Tests'!$I$2:$I$107,MATCH($H8,'Covenant Tests'!$J$2:$J$107,0))="","",INDEX('Covenant Tests'!$I$2:$I$107,MATCH($H8,'Covenant Tests'!$J$2:$J$107,0))),"Source record missing") -> Loan Agreement 3.4(d) | H8: CT006
A9: =IFERROR(IF(INDEX('Covenant Tests'!$A$2:$A$107,MATCH($H9,'Covenant Tests'!$J$2:$J$107,0))="","",INDEX('Covenant Tests'!$A$2:$A$107,MATCH($H9,'Covenant Tests'!$J$2:$J$107,0))),"Source record missing") -> Fort Collins Vine | B9: =IFERROR(IF(INDEX('Covenant Tests'!$B$2:$B$107,MATCH($H9,'Covenant Tests'!$J$2:$J$107,0))="","",INDEX('Covenant Tests'!$B$2:$B$107,MATCH($H9,'Covenant Tests'!$J$2:$J$107,0))),"Source record missing") -> Western-Southern | C9: =IFERROR(IF(INDEX('Covenant Tests'!$E$2:$E$107,MATCH($H9,'Covenant Tests'!$J$2:$J$107,0))="","",INDEX('Covenant Tests'!$E$2:$E$107,MATCH($H9,'Covenant Tests'!$J$2:$J$107,0))),"Source record missing") -> Ongoing | D9: =HYPERLINK("#'Covenant Tests'!A"&(MATCH($H9,'Covenant Tests'!$J$2:$J$107,0)+1),INDEX('Covenant Tests'!$C$2:$C$107,MATCH($H9,'Covenant Tests'!$J$2:$J$107,0))) -> Stabilization: NOI | E9: =IFERROR(IF(INDEX('Covenant Tests'!$D$2:$D$107,MATCH($H9,'Covenant Tests'!$J$2:$J$107,0))="","",INDEX('Covenant Tests'!$D$2:$D$107,MATCH($H9,'Covenant Tests'!$J$2:$J$107,0))),"Source record missing") -> $6,775,000 annualized for three straight months | F9: =IFERROR(IF(INDEX('Covenant Tests'!$G$2:$G$107,MATCH($H9,'Covenant Tests'!$J$2:$J$107,0))="","",INDEX('Covenant Tests'!$G$2:$G$107,MATCH($H9,'Covenant Tests'!$J$2:$J$107,0))),"Source record missing") -> Ongoing; until met, by June 2028 | G9: =IFERROR(IF(INDEX('Covenant Tests'!$I$2:$I$107,MATCH($H9,'Covenant Tests'!$J$2:$J$107,0))="","",INDEX('Covenant Tests'!$I$2:$I$107,MATCH($H9,'Covenant Tests'!$J$2:$J$107,0))),"Source record missing") -> Stabilization Guaranty; Note 5.6 | H9: CT012
A10: =IFERROR(IF(INDEX('Covenant Tests'!$A$2:$A$107,MATCH($H10,'Covenant Tests'!$J$2:$J$107,0))="","",INDEX('Covenant Tests'!$A$2:$A$107,MATCH($H10,'Covenant Tests'!$J$2:$J$107,0))),"Source record missing") -> Ellenton | B10: =IFERROR(IF(INDEX('Covenant Tests'!$B$2:$B$107,MATCH($H10,'Covenant Tests'!$J$2:$J$107,0))="","",INDEX('Covenant Tests'!$B$2:$B$107,MATCH($H10,'Covenant Tests'!$J$2:$J$107,0))),"Source record missing") -> Kayne Anderson | C10: =IFERROR(IF(INDEX('Covenant Tests'!$E$2:$E$107,MATCH($H10,'Covenant Tests'!$J$2:$J$107,0))="","",INDEX('Covenant Tests'!$E$2:$E$107,MATCH($H10,'Covenant Tests'!$J$2:$J$107,0))),"Source record missing") -> Event-driven | D10: =HYPERLINK("#'Covenant Tests'!A"&(MATCH($H10,'Covenant Tests'!$J$2:$J$107,0)+1),INDEX('Covenant Tests'!$C$2:$C$107,MATCH($H10,'Covenant Tests'!$J$2:$J$107,0))) -> Interest reserve replenishment | E10: =IFERROR(IF(INDEX('Covenant Tests'!$D$2:$D$107,MATCH($H10,'Covenant Tests'!$J$2:$J$107,0))="","",INDEX('Covenant Tests'!$D$2:$D$107,MATCH($H10,'Covenant Tests'!$J$2:$J$107,0))),"Source record missing") -> Lesser of the deficiency or the amount to reach 1.0x Implied DSCR | F10: =IFERROR(IF(INDEX('Covenant Tests'!$G$2:$G$107,MATCH($H10,'Covenant Tests'!$J$2:$J$107,0))="","",INDEX('Covenant Tests'!$G$2:$G$107,MATCH($H10,'Covenant Tests'!$J$2:$J$107,0))),"Source record missing") -> On lender notice | G10: =IFERROR(IF(INDEX('Covenant Tests'!$I$2:$I$107,MATCH($H10,'Covenant Tests'!$J$2:$J$107,0))="","",INDEX('Covenant Tests'!$I$2:$I$107,MATCH($H10,'Covenant Tests'!$J$2:$J$107,0))),"Source record missing") -> Loan Agreement 6.1(b) | H10: CT017
A11: =IFERROR(IF(INDEX('Covenant Tests'!$A$2:$A$107,MATCH($H11,'Covenant Tests'!$J$2:$J$107,0))="","",INDEX('Covenant Tests'!$A$2:$A$107,MATCH($H11,'Covenant Tests'!$J$2:$J$107,0))),"Source record missing") -> Panama City Beach | B11: =IFERROR(IF(INDEX('Covenant Tests'!$B$2:$B$107,MATCH($H11,'Covenant Tests'!$J$2:$J$107,0))="","",INDEX('Covenant Tests'!$B$2:$B$107,MATCH($H11,'Covenant Tests'!$J$2:$J$107,0))),"Source record missing") -> Merchants Bank of Indiana | C11: =IFERROR(IF(INDEX('Covenant Tests'!$E$2:$E$107,MATCH($H11,'Covenant Tests'!$J$2:$J$107,0))="","",INDEX('Covenant Tests'!$E$2:$E$107,MATCH($H11,'Covenant Tests'!$J$2:$J$107,0))),"Source record missing") -> Ongoing | D11: =HYPERLINK("#'Covenant Tests'!A"&(MATCH($H11,'Covenant Tests'!$J$2:$J$107,0)+1),INDEX('Covenant Tests'!$C$2:$C$107,MATCH($H11,'Covenant Tests'!$J$2:$J$107,0))) -> Rent collection escrow release | E11: =IFERROR(IF(INDEX('Covenant Tests'!$D$2:$D$107,MATCH($H11,'Covenant Tests'!$J$2:$J$107,0))="","",INDEX('Covenant Tests'!$D$2:$D$107,MATCH($H11,'Covenant Tests'!$J$2:$J$107,0))),"Source record missing") -> DSCR 1.20x and $509,914 monthly rent collections, 3 straight months | F11: =IFERROR(IF(INDEX('Covenant Tests'!$G$2:$G$107,MATCH($H11,'Covenant Tests'!$J$2:$J$107,0))="","",INDEX('Covenant Tests'!$G$2:$G$107,MATCH($H11,'Covenant Tests'!$J$2:$J$107,0))),"Source record missing") -> Ongoing; until released | G11: =IFERROR(IF(INDEX('Covenant Tests'!$I$2:$I$107,MATCH($H11,'Covenant Tests'!$J$2:$J$107,0))="","",INDEX('Covenant Tests'!$I$2:$I$107,MATCH($H11,'Covenant Tests'!$J$2:$J$107,0))),"Source record missing") -> Loan Agreement 6.2 | H11: CT018
A12: =IFERROR(IF(INDEX('Covenant Tests'!$A$2:$A$107,MATCH($H12,'Covenant Tests'!$J$2:$J$107,0))="","",INDEX('Covenant Tests'!$A$2:$A$107,MATCH($H12,'Covenant Tests'!$J$2:$J$107,0))),"Source record missing") -> Port St Lucie | B12: =IFERROR(IF(INDEX('Covenant Tests'!$B$2:$B$107,MATCH($H12,'Covenant Tests'!$J$2:$J$107,0))="","",INDEX('Covenant Tests'!$B$2:$B$107,MATCH($H12,'Covenant Tests'!$J$2:$J$107,0))),"Source record missing") -> Blackstone / FGL | C12: =IFERROR(IF(INDEX('Covenant Tests'!$E$2:$E$107,MATCH($H12,'Covenant Tests'!$J$2:$J$107,0))="","",INDEX('Covenant Tests'!$E$2:$E$107,MATCH($H12,'Covenant Tests'!$J$2:$J$107,0))),"Source record missing") -> Ongoing | D12: =HYPERLINK("#'Covenant Tests'!A"&(MATCH($H12,'Covenant Tests'!$J$2:$J$107,0)+1),INDEX('Covenant Tests'!$C$2:$C$107,MATCH($H12,'Covenant Tests'!$J$2:$J$107,0))) -> Cash trap since closing | E12: =IFERROR(IF(INDEX('Covenant Tests'!$D$2:$D$107,MATCH($H12,'Covenant Tests'!$J$2:$J$107,0))="","",INDEX('Covenant Tests'!$D$2:$D$107,MATCH($H12,'Covenant Tests'!$J$2:$J$107,0))),"Source record missing") -> Released at NOI of $3,000,000 annualized for three straight months | F12: =IFERROR(IF(INDEX('Covenant Tests'!$G$2:$G$107,MATCH($H12,'Covenant Tests'!$J$2:$J$107,0))="","",INDEX('Covenant Tests'!$G$2:$G$107,MATCH($H12,'Covenant Tests'!$J$2:$J$107,0))),"Source record missing") -> Ongoing; until cured | G12: =IFERROR(IF(INDEX('Covenant Tests'!$I$2:$I$107,MATCH($H12,'Covenant Tests'!$J$2:$J$107,0))="","",INDEX('Covenant Tests'!$I$2:$I$107,MATCH($H12,'Covenant Tests'!$J$2:$J$107,0))),"Source record missing") -> Loan Agreement 1.1, Cash Trap Event | H12: CT022
A13: =IFERROR(IF(INDEX('Covenant Tests'!$A$2:$A$107,MATCH($H13,'Covenant Tests'!$J$2:$J$107,0))="","",INDEX('Covenant Tests'!$A$2:$A$107,MATCH($H13,'Covenant Tests'!$J$2:$J$107,0))),"Source record missing") -> Port St Lucie | B13: =IFERROR(IF(INDEX('Covenant Tests'!$B$2:$B$107,MATCH($H13,'Covenant Tests'!$J$2:$J$107,0))="","",INDEX('Covenant Tests'!$B$2:$B$107,MATCH($H13,'Covenant Tests'!$J$2:$J$107,0))),"Source record missing") -> Blackstone / FGL | C13: =IFERROR(IF(INDEX('Covenant Tests'!$E$2:$E$107,MATCH($H13,'Covenant Tests'!$J$2:$J$107,0))="","",INDEX('Covenant Tests'!$E$2:$E$107,MATCH($H13,'Covenant Tests'!$J$2:$J$107,0))),"Source record missing") -> Ongoing | D13: =HYPERLINK("#'Covenant Tests'!A"&(MATCH($H13,'Covenant Tests'!$J$2:$J$107,0)+1),INDEX('Covenant Tests'!$C$2:$C$107,MATCH($H13,'Covenant Tests'!$J$2:$J$107,0))) -> Cash Collateral Reserve release | E13: =IFERROR(IF(INDEX('Covenant Tests'!$D$2:$D$107,MATCH($H13,'Covenant Tests'!$J$2:$J$107,0))="","",INDEX('Covenant Tests'!$D$2:$D$107,MATCH($H13,'Covenant Tests'!$J$2:$J$107,0))),"Source record missing") -> Debt Yield 8.25% for two straight quarters | F13: =IFERROR(IF(INDEX('Covenant Tests'!$G$2:$G$107,MATCH($H13,'Covenant Tests'!$J$2:$J$107,0))="","",INDEX('Covenant Tests'!$G$2:$G$107,MATCH($H13,'Covenant Tests'!$J$2:$J$107,0))),"Source record missing") -> Ongoing; until released | G13: =IFERROR(IF(INDEX('Covenant Tests'!$I$2:$I$107,MATCH($H13,'Covenant Tests'!$J$2:$J$107,0))="","",INDEX('Covenant Tests'!$I$2:$I$107,MATCH($H13,'Covenant Tests'!$J$2:$J$107,0))),"Source record missing") -> Loan Agreement 7.5 | H13: CT024
A14: =IFERROR(IF(INDEX('Covenant Tests'!$A$2:$A$107,MATCH($H14,'Covenant Tests'!$J$2:$J$107,0))="","",INDEX('Covenant Tests'!$A$2:$A$107,MATCH($H14,'Covenant Tests'!$J$2:$J$107,0))),"Source record missing") -> Port St Lucie | B14: =IFERROR(IF(INDEX('Covenant Tests'!$B$2:$B$107,MATCH($H14,'Covenant Tests'!$J$2:$J$107,0))="","",INDEX('Covenant Tests'!$B$2:$B$107,MATCH($H14,'Covenant Tests'!$J$2:$J$107,0))),"Source record missing") -> Blackstone / FGL | C14: =IFERROR(IF(INDEX('Covenant Tests'!$E$2:$E$107,MATCH($H14,'Covenant Tests'!$J$2:$J$107,0))="","",INDEX('Covenant Tests'!$E$2:$E$107,MATCH($H14,'Covenant Tests'!$J$2:$J$107,0))),"Source record missing") -> Ongoing | D14: =HYPERLINK("#'Covenant Tests'!A"&(MATCH($H14,'Covenant Tests'!$J$2:$J$107,0)+1),INDEX('Covenant Tests'!$C$2:$C$107,MATCH($H14,'Covenant Tests'!$J$2:$J$107,0))) -> Additional Cash Collateral release | E14: =IFERROR(IF(INDEX('Covenant Tests'!$D$2:$D$107,MATCH($H14,'Covenant Tests'!$J$2:$J$107,0))="","",INDEX('Covenant Tests'!$D$2:$D$107,MATCH($H14,'Covenant Tests'!$J$2:$J$107,0))),"Source record missing") -> NOI of $3,000,000 | F14: =IFERROR(IF(INDEX('Covenant Tests'!$G$2:$G$107,MATCH($H14,'Covenant Tests'!$J$2:$J$107,0))="","",INDEX('Covenant Tests'!$G$2:$G$107,MATCH($H14,'Covenant Tests'!$J$2:$J$107,0))),"Source record missing") -> Ongoing; until released | G14: =IFERROR(IF(INDEX('Covenant Tests'!$I$2:$I$107,MATCH($H14,'Covenant Tests'!$J$2:$J$107,0))="","",INDEX('Covenant Tests'!$I$2:$I$107,MATCH($H14,'Covenant Tests'!$J$2:$J$107,0))),"Source record missing") -> Loan Agreement 7.5 | H14: CT025
A15: =IFERROR(IF(INDEX('Covenant Tests'!$A$2:$A$107,MATCH($H15,'Covenant Tests'!$J$2:$J$107,0))="","",INDEX('Covenant Tests'!$A$2:$A$107,MATCH($H15,'Covenant Tests'!$J$2:$J$107,0))),"Source record missing") -> St. Augustine | B15: =IFERROR(IF(INDEX('Covenant Tests'!$B$2:$B$107,MATCH($H15,'Covenant Tests'!$J$2:$J$107,0))="","",INDEX('Covenant Tests'!$B$2:$B$107,MATCH($H15,'Covenant Tests'!$J$2:$J$107,0))),"Source record missing") -> Simmons | C15: =IFERROR(IF(INDEX('Covenant Tests'!$E$2:$E$107,MATCH($H15,'Covenant Tests'!$J$2:$J$107,0))="","",INDEX('Covenant Tests'!$E$2:$E$107,MATCH($H15,'Covenant Tests'!$J$2:$J$107,0))),"Source record missing") -> Ongoing | D15: =HYPERLINK("#'Covenant Tests'!A"&(MATCH($H15,'Covenant Tests'!$J$2:$J$107,0)+1),INDEX('Covenant Tests'!$C$2:$C$107,MATCH($H15,'Covenant Tests'!$J$2:$J$107,0))) -> Cash trap before stabilization | E15: =IFERROR(IF(INDEX('Covenant Tests'!$D$2:$D$107,MATCH($H15,'Covenant Tests'!$J$2:$J$107,0))="","",INDEX('Covenant Tests'!$D$2:$D$107,MATCH($H15,'Covenant Tests'!$J$2:$J$107,0))),"Source record missing") -> Released at DSCR 1.20x | F15: =IFERROR(IF(INDEX('Covenant Tests'!$G$2:$G$107,MATCH($H15,'Covenant Tests'!$J$2:$J$107,0))="","",INDEX('Covenant Tests'!$G$2:$G$107,MATCH($H15,'Covenant Tests'!$J$2:$J$107,0))),"Source record missing") -> Ongoing; until Initial Stabilization | G15: =IFERROR(IF(INDEX('Covenant Tests'!$I$2:$I$107,MATCH($H15,'Covenant Tests'!$J$2:$J$107,0))="","",INDEX('Covenant Tests'!$I$2:$I$107,MATCH($H15,'Covenant Tests'!$J$2:$J$107,0))),"Source record missing") -> Loan Agreement 10.21 | H15: CT030
A16: =IFERROR(IF(INDEX('Covenant Tests'!$A$2:$A$107,MATCH($H16,'Covenant Tests'!$J$2:$J$107,0))="","",INDEX('Covenant Tests'!$A$2:$A$107,MATCH($H16,'Covenant Tests'!$J$2:$J$107,0))),"Source record missing") -> St. Augustine | B16: =IFERROR(IF(INDEX('Covenant Tests'!$B$2:$B$107,MATCH($H16,'Covenant Tests'!$J$2:$J$107,0))="","",INDEX('Covenant Tests'!$B$2:$B$107,MATCH($H16,'Covenant Tests'!$J$2:$J$107,0))),"Source record missing") -> Simmons | C16: =IFERROR(IF(INDEX('Covenant Tests'!$E$2:$E$107,MATCH($H16,'Covenant Tests'!$J$2:$J$107,0))="","",INDEX('Covenant Tests'!$E$2:$E$107,MATCH($H16,'Covenant Tests'!$J$2:$J$107,0))),"Source record missing") -> Event-driven | D16: =HYPERLINK("#'Covenant Tests'!A"&(MATCH($H16,'Covenant Tests'!$J$2:$J$107,0)+1),INDEX('Covenant Tests'!$C$2:$C$107,MATCH($H16,'Covenant Tests'!$J$2:$J$107,0))) -> Cash trap after stabilization | E16: =IFERROR(IF(INDEX('Covenant Tests'!$D$2:$D$107,MATCH($H16,'Covenant Tests'!$J$2:$J$107,0))="","",INDEX('Covenant Tests'!$D$2:$D$107,MATCH($H16,'Covenant Tests'!$J$2:$J$107,0))),"Source record missing") -> DSCR under 1.15x for 3 straight months | F16: =IFERROR(IF(INDEX('Covenant Tests'!$G$2:$G$107,MATCH($H16,'Covenant Tests'!$J$2:$J$107,0))="","",INDEX('Covenant Tests'!$G$2:$G$107,MATCH($H16,'Covenant Tests'!$J$2:$J$107,0))),"Source record missing") -> After stabilization; monthly | G16: =IFERROR(IF(INDEX('Covenant Tests'!$I$2:$I$107,MATCH($H16,'Covenant Tests'!$J$2:$J$107,0))="","",INDEX('Covenant Tests'!$I$2:$I$107,MATCH($H16,'Covenant Tests'!$J$2:$J$107,0))),"Source record missing") -> Loan Agreement 10.21 | H16: CT031
... A30: =IFERROR(IF(INDEX('Covenant Tests'!$A$2:$A$107,MATCH($H30,'Covenant Tests'!$J$2:$J$107,0))="","",INDEX('Covenant Tests'!$A$2:$A$107,MATCH($H30,'Covenant Tests'!$J$2:$J$107,0))),"Source record missing") -> Overland Park | B30: =IFERROR(IF(INDEX('Covenant Tests'!$B$2:$B$107,MATCH($H30,'Covenant Tests'!$J$2:$J$107,0))="","",INDEX('Covenant Tests'!$B$2:$B$107,MATCH($H30,'Covenant Tests'!$J$2:$J$107,0))),"Source record missing") -> Simmons | C30: =IFERROR(IF(INDEX('Covenant Tests'!$E$2:$E$107,MATCH($H30,'Covenant Tests'!$J$2:$J$107,0))="","",INDEX('Covenant Tests'!$E$2:$E$107,MATCH($H30,'Covenant Tests'!$J$2:$J$107,0))),"Source record missing") -> Ongoing | D30: =HYPERLINK("#'Covenant Tests'!A"&(MATCH($H30,'Covenant Tests'!$J$2:$J$107,0)+1),INDEX('Covenant Tests'!$C$2:$C$107,MATCH($H30,'Covenant Tests'!$J$2:$J$107,0))) -> Loan to cost | E30: =IFERROR(IF(INDEX('Covenant Tests'!$D$2:$D$107,MATCH($H30,'Covenant Tests'!$J$2:$J$107,0))="","",INDEX('Covenant Tests'!$D$2:$D$107,MATCH($H30,'Covenant Tests'!$J$2:$J$107,0))),"Source record missing") -> 65% of project cost | F30: =IFERROR(IF(INDEX('Covenant Tests'!$G$2:$G$107,MATCH($H30,'Covenant Tests'!$J$2:$J$107,0))="","",INDEX('Covenant Tests'!$G$2:$G$107,MATCH($H30,'Covenant Tests'!$J$2:$J$107,0))),"Source record missing") -> At all times | G30: =IFERROR(IF(INDEX('Covenant Tests'!$I$2:$I$107,MATCH($H30,'Covenant Tests'!$J$2:$J$107,0))="","",INDEX('Covenant Tests'!$I$2:$I$107,MATCH($H30,'Covenant Tests'!$J$2:$J$107,0))),"Source record missing") -> Loan Agreement, Loan to Cost | H30: CT103

Sheet Covenant Tests
A1: Property | B1: Lender | C1: Test | D1: Threshold | E1: Timing Type | F1: First Test Date | G1: Timing / Frequency | H1: In 2027 | I1: Reference | J1: Covenant ID
A2: Dove Valley | B2: Nationwide | C2: Extension: Net Cash Flow coverage | D2: 105% of interest at the 8.50% Base Rate | E2: One-time | F2: 46692 | G2: Once | H2: Yes | I2: Loan Agreement 3.7(g) | J2: CT001
A3: Dove Valley | B3: Nationwide | C3: Extension: LTV | D3: 65% of fair market value | E3: One-time | F3: 46692 | G3: Once | H3: Yes | I3: Loan Agreement 3.7(f) | J3: CT002
A4: Dove Valley | B4: Nationwide | C4: Cash sweep and distribution block | D4: Until final completion, DSCR 1.00x on trailing 3 months and capitalized interest repaid | E4: Ongoing | G4: Ongoing; monthly | H4: Yes | I4: Loan Agreement 3.5, 7.14 | J4: CT003
A5: Dove Valley | B5: Nationwide | C5: Interest reserve top-up | D5: Reserve short of projected current pay interest, or loan to cost at 70% | E5: Event-driven | G5: On lender notice | H5: Yes | I5: Loan Agreement 3.4(d) | J5: CT004
A6: Spectrum Loop | B6: Nationwide | C6: Cash sweep and distribution block | D6: Until final completion, DSCR 1.00x on trailing 3 months and capitalized interest repaid | E6: Ongoing | G6: Ongoing; monthly | H6: Yes | I6: Loan Agreement 3.5, 7.14 | J6: CT005
A7: Spectrum Loop | B7: Nationwide | C7: Interest reserve top-up | D7: Reserve short of projected current pay interest, or loan to cost at 70% | E7: Event-driven | G7: On lender notice | H7: Yes | I7: Loan Agreement 3.4(d) | J7: CT006
A8: Spectrum Loop | B8: Nationwide | C8: Extension: Net Cash Flow coverage | D8: 105% of interest at the 8.25% Base Rate | E8: One-time | F8: 47014 | G8: Once | H8: No | I8: Loan Agreement 3.7(g) | J8: CT007
A9: Spectrum Loop | B9: Nationwide | C9: Extension: LTV | D9: 66% of fair market value | E9: One-time | F9: 47014 | G9: Once | H9: No | I9: Loan Agreement 3.7(f) | J9: CT008
A10: Fort Collins Shields | B10: Starwood | C10: Cash trap: Debt Yield | D10: 6.50% (6.75% for two straight quarters to release) | E10: Recurring | F10: 46608 | G10: Quarterly from the August 2027 payment date | H10: Yes | I10: Loan Agreement 1.1, Cash Management Event | J10: CT009
A11: Fort Collins Shields | B11: Starwood | C11: First extension: Debt Yield | D11: 7.00% | E11: One-time | F11: 46974 | G11: Once | H11: No | I11: Loan Agreement 2.2.8(c) | J11: CT010
A12: Fort Collins Shields | B12: Starwood | C12: Second extension: Debt Yield | D12: 7.25% | E12: One-time | F12: 47339 | G12: Once | H12: No | I12: Loan Agreement 2.2.8(d) | J12: CT011
A13: Fort Collins Vine | B13: Western-Southern | C13: Stabilization: NOI | D13: $6,775,000 annualized for three straight months | E13: Ongoing | G13: Ongoing; until met, by June 2028 | H13: Yes | I13: Stabilization Guaranty; Note 5.6 | J13: CT012
A14: Fort Collins Vine | B14: Western-Southern | C14: Paydown test: Debt Yield | D14: 9.75% as of 6/30/2028, unless Stabilization is met | E14: One-time | F14: 46934 | G14: Once | H14: No | I14: Note 5.6 | J14: CT013
A15: Ellenton | B15: Kayne Anderson | C15: Debt Yield | D15: 6.00% (7.00% to release) | E15: Recurring | F15: 46660 | G15: Quarterly | H15: Yes | I15: Loan Agreement 2.5(a) | J15: CT014
A16: Ellenton | B16: Kayne Anderson | C16: Implied DSCR | D16: 1.00x (1.05x to release) | E16: Recurring | F16: 46660 | G16: Quarterly | H16: Yes | I16: Loan Agreement 2.5(b) | J16: CT015
A17: Ellenton | B17: Kayne Anderson | C17: Extension: Debt Yield | D17: 7.00% first extension, 7.25% second | E17: Recurring | F17: 47266 | G17: Each extension | H17: No | I17: Loan Agreement 2.3.3 | J17: CT016
A18: Ellenton | B18: Kayne Anderson | C18: Interest reserve replenishment | D18: Lesser of the deficiency or the amount to reach 1.0x Implied DSCR | E18: Event-driven | G18: On lender notice | H18: Yes | I18: Loan Agreement 6.1(b) | J18: CT017
A19: Panama City Beach | B19: Merchants Bank of Indiana | C19: Rent collection escrow release | D19: DSCR 1.20x and $509,914 monthly rent collections, 3 straight months | E19: Ongoing | G19: Ongoing; until released | H19: Yes | I19: Loan Agreement 6.2 | J19: CT018
A20: Ponte Vedra | B20: Trustmark | C20: DSCR covenant | D20: 1.00x | E20: Recurring | F20: 46996 | G20: From 8/31/2028 | H20: No | I20: Loan Agreement 6.28 | J20: CT019
A21: Ponte Vedra | B21: Trustmark | C21: Extension: DSCR | D21: 1.25x | E21: One-time | F21: 47149 | G21: Once | H21: No | I21: Loan Agreement 2.2(c), 6.28 | J21: CT020
A22: Ponte Vedra | B22: Trustmark | C22: Extension: LTV | D22: 61% of as-is value | E22: One-time | F22: 47162 | G22: Once | H22: No | I22: Loan Agreement 2.2(c) | J22: CT021
A23: Port St Lucie | B23: Blackstone / FGL | C23: Cash trap since closing | D23: Released at NOI of $3,000,000 annualized for three straight months | E23: Ongoing | G23: Ongoing; until cured | H23: Yes | I23: Loan Agreement 1.1, Cash Trap Event | J23: CT022
A24: Port St Lucie | B24: Blackstone / FGL | C24: Cash trap: Debt Yield and DSCR | D24: 8.00% and 1.25x (8.50% and 1.35x after 9/1/2028) | E24: Recurring | F24: 46477 | G24: Quarterly | H24: Yes | I24: Loan Agreement 1.1, Cash Trap Event | J24: CT023
A25: Port St Lucie | B25: Blackstone / FGL | C25: Cash Collateral Reserve release | D25: Debt Yield 8.25% for two straight quarters | E25: Ongoing | G25: Ongoing; until released | H25: Yes | I25: Loan Agreement 7.5 | J25: CT024
A26: Port St Lucie | B26: Blackstone / FGL | C26: Additional Cash Collateral release | D26: NOI of $3,000,000 | E26: Ongoing | G26: Ongoing; until released | H26: Yes | I26: Loan Agreement 7.5 | J26: CT025
A27: Port St Lucie | B27: Blackstone / FGL | C27: First extension: Debt Yield | D27: 8.50% | E27: One-time | F27: 46997 | G27: Once | H27: No | I27: Loan Agreement 2.9 | J27: CT026
A28: Port St Lucie | B28: Blackstone / FGL | C28: Second extension: Debt Yield | D28: 9.00% | E28: One-time | F28: 47362 | G28: Once | H28: No | I28: Loan Agreement 2.9 | J28: CT027
A29: Sarasota | B29: Stifel | C29: DSCR covenant | D29: 1.20x | E29: Event-driven | G29: After maturity; each 12/31 and 6/30 from 7/1/2026 | H29: No | I29: Loan Agreement 11.1 | J29: CT028
A30: St. Augustine | B30: Simmons | C30: DSCR covenant | D30: 1.35x | E30: Recurring | F30: 46203 | G30: Quarterly; trailing 3, 6, 9, then 12 months | H30: Yes | I30: Loan Agreement, Events of Default | J30: CT029
A31: St. Augustine | B31: Simmons | C31: Cash trap before stabilization | D31: Released at DSCR 1.20x | E31: Ongoing | G31: Ongoing; until Initial Stabilization | H31: Yes | I31: Loan Agreement 10.21 | J31: CT030
A32: St. Augustine | B32: Simmons | C32: Cash trap after stabilization | D32: DSCR under 1.15x for 3 straight months | E32: Event-driven | G32: After stabilization; monthly | H32: Check | I32: Loan Agreement 10.21 | J32: CT031
A33: St. Augustine | B33: Simmons | C33: Loan to cost | D33: 57.50% of project cost | E33: Ongoing | G33: At all times | H33: Yes | I33: Loan Agreement, Loan to Cost | J33: CT032
A34: St. Augustine | B34: Simmons | C34: Distribution block | D34: No distributions until the loan is repaid, except tax distributions | E34: Ongoing | G34: At all times | H34: Yes | I34: Loan Agreement, Distributions | J34: CT033
A35: St. Augustine | B35: Simmons | C35: Extension: DSCR | D35: 1.25x | E35: One-time | F35: 46748 | G35: Once | H35: Yes | I35: Note, Extension | J35: CT034
A36: St. Augustine | B36: Simmons | C36: Extension: LTV | D36: 55% of as-is value | E36: One-time | F36: 46748 | G36: Once | H36: Yes | I36: Note, Extension | J36: CT035
A37: Venice | B37: UMB | C37: DSCR covenant | D37: 1.10x | E37: Recurring | F37: 46339 | G37: 11/13/2026, then each 6/30 and 12/31 | H37: Yes | I37: Loan Agreement 5.18 | J37: CT036
A38: Venice | B38: UMB | C38: Occupancy | D38: 87.5% leased | E38: Recurring | F38: 46339 | G38: Semi-annual | H38: Yes | I38: Loan Agreement 5.24 | J38: CT037
A39: Venice | B39: UMB | C39: Extension: DSCR | D39: 1.10x | E39: One-time | F39: 46507 | G39: Once | H39: Yes | I39: Note, Section 1 | J39: CT038
A40: Venice | B40: UMB | C40: Extension: LTV | D40: 70% of as-is value, if bank requires an appraisal | E40: One-time | F40: 46519 | G40: Once | H40: Yes | I40: Note, Section 1 | J40: CT039
...

Sheet Test Calculations
A1: Property | B1: Lender | C1: Calc Type | D1: Debt Service | E1: Balance Used | F1: Amortization (Years) | G1: Loan Index | H1: Loan Margin | I1: Loan Rate Floor | J1: Treasury Spread | K1: Sizing Rate | L1: Mortgage Constant | M1: Treasury Rate Source | N1: NOI Period | O1: Revenue | P1: Expenses | Q1: Debt Yield / LTV | R1: Reference
A2: Dove Valley | B2: Nationwide | C2: Fixed rate, interest only | D2: Interest on the loan, including capitalized interest, at the 8.50% Base Rate. Used for the extension and distribution tests. | E2: Outstanding balance, including capitalized interest | G2: Fixed: 8.50% Base Rate | N2: Extension: trailing 12 months. Distributions: trailing 3 months, annualized. | O2: Gross revenues from the project. | P2: Greater of pro forma or actual, with a $200 per unit reserve and the greatest of actual, the appraisal or a 3% management fee. | Q2: LTV: outstanding balance over fair market value, as the lender determines (65%). | R2: Loan Agreement definitions: Net Cash Flow, Operating Expenses, Calendar Period, Debt Service Requirement
A3: Spectrum Loop | B3: Nationwide | C3: Fixed rate, interest only | D3: Interest on the loan, including capitalized interest, at the 8.25% Base Rate. Used for the extension and distribution tests. | E3: Outstanding balance, including capitalized interest | G3: Fixed: 8.25% Base Rate | N3: Extension: trailing 12 months. Distributions: trailing 3 months, annualized. | O3: Gross revenues from the project. | P3: Greater of pro forma or actual, with a $200 per unit reserve and the greatest of actual, the appraisal or a 3% management fee. | Q3: LTV: outstanding balance over fair market value, as the lender determines (66%). | R3: Loan Agreement definitions: Net Cash Flow, Operating Expenses, Calendar Period, Debt Service Requirement
A4: Fort Collins Shields | B4: Starwood | C4: No DSCR test | D4: Not used in the cash trap or extension tests. The rate cap strike resets to hold a 1.10x DSCR. | G4: 1M Term SOFR | H4: 0.023 | N4: Residential revenue: trailing 3 months, annualized. Expenses: trailing 12 months. | O4: Residential income with vacancy at the greater of actual or 5%. | P4: Actual, with the greater of actual or a 3.50% management fee and a $250 per unit reserve. | Q4: Debt Yield: underwritten net cash flow over outstanding principal. | R4: Loan Agreement definitions: Debt Yield, UNCF
A5: Fort Collins Vine | B5: Western-Southern | C5: No DSCR test | D5: Not used. | G5: SOFR | H5: 0.035 | I5: 3.25% index floor; 6.75% all-in floor | N5: Monthly NOI, annualized; three straight months for Stabilization | O5: Residential rent only, capped at 95% occupancy. | P5: Actual, with the greater of actual or a 4% management fee and a $200 per unit reserve. | Q5: Debt Yield: NOI over outstanding principal. A miss is cured by paying down to 9.75%. | R5: Note 5.6; Stabilization Guaranty
A6: Ellenton | B6: Kayne Anderson | C6: Actual debt service | D6: Interest only: principal balance times the actual average rate (SOFR + 2.60%) for the trailing 3 months, net of the rate cap. | E6: Outstanding principal | G6: 1M Term SOFR | H6: 0.026 | I6: 2.75% index floor | N6: Trailing 3 months, annualized | O6: Operating revenue on an accrual basis, capped at 95% physical occupancy. Excludes free rent, concessions and non-recurring revenue. | P6: Actual, with the greater of actual or a 3% management fee and a $250 per unit annual reserve. | Q6: Debt Yield: NOI over principal balance. | R6: Loan Agreement definitions: Adjusted NOI, Implied Debt Service, Debt Yield
A7: Panama City Beach | B7: Merchants Bank of Indiana | C7: Note rate, amortized | D7: Outstanding principal amortized over 30 years at the note rate. | E7: Outstanding principal | F7: 30 | G7: SOFR | H7: 0.0275 | I7: 2.75% all-in floor | N7: Not stated ("specified period") | O7: Net income plus interest, depreciation and amortization, from borrower financial statements. Rent test: gross collections from third-party residential leases, excluding extraordinary income. | P7: As reported, less the replacement reserve amount. | R7: Loan Agreement definitions: Debt Service Coverage Ratio, Debt Service, Monthly Rent Collection Amount
